<?xml version="1.0"?>
<robot xmlns:xacro="http://www.ros.org/wiki/xacro" name="manipulator">

<material name="blue">
<color rgba="0 0 0.8 1"/>
</material>
<material name="grey">
<color rgba="0.5 0.5 0.5 1"/>
</material>
<material name="orange">
<color rgba="1.0 0.5 0 1"/>
</material>
<link name="base_footprint"/>
<joint name="virtual_joint" type="fixed">
<parent link="base_footprint"/>
<child link="base_link"/>
<origin xyz="0 0 0" rpy="0 0 0"/>
</joint>
<link name="base_link">
<visual>
<geometry>
<cylinder radius="0.2" length="0.1"/>
</geometry>
<material name="grey"/>
</visual>
</link>
<joint name="joint_1" type="revolute">
<parent link="base_link"/>
<child link="link_1"/>
<origin xyz="0 0 0.05" rpy="0 0 0"/>
<axis xyz="0 0 1"/>
<limit lower="-3.14" upper="3.14" effort="10" velocity="1.0"/>
</joint>
<link name="link_1">
<visual>
<geometry>
<cylinder radius="0.05" length="0.2"/>
</geometry>
<origin xyz="0 0 0.1" rpy="0 0 0"/>
<material name="blue"/>
</visual>
</link>
<joint name="joint_2" type="revolute">
<parent link="link_1"/>
<child link="link_2"/>
<origin xyz="0 0 0.2" rpy="0 0 0"/>
<axis xyz="0 1 0"/>
<limit lower="-1.57" upper="1.57" effort="10" velocity="1.0"/>
</joint>
<link name="link_2">
<visual>
<geometry>
<box size="0.05 0.05 0.4"/>
</geometry>
<origin xyz="0 0 0.2" rpy="0 0 0"/>
<material name="orange"/>
</visual>
</link>
<joint name="joint_3" type="revolute">
<parent link="link_2"/>
<child link="link_3"/>
<origin xyz="0 0 0.4" rpy="0 0 0"/>
<axis xyz="0 1 0"/>
<limit lower="-1.57" upper="1.57" effort="10" velocity="1.0"/>
</joint>
<link name="link_3">
<visual>
<geometry>
<box size="0.05 0.05 0.3"/>
</geometry>
<origin xyz="0 0 0.15" rpy="0 0 0"/>
<material name="blue"/>
</visual>
</link>
</robot>