<?xml version="1.0"?>
<robot xmlns:xacro="http://www.ros.org/wiki/xacro" name="manipulator">

  <material name="blue"><color rgba="0 0 0.8 1"/></material>
  <material name="grey"><color rgba="0.5 0.5 0.5 1"/></material>
  <material name="orange"><color rgba="1.0 0.5 0 1"/></material>
  <material name="black"><color rgba="0 0 0 1"/></material>

  <xacro:macro name="cylinder_inertia" params="m r h">
    <inertial>
      <origin xyz="0 0 ${h/2}" rpy="0 0 0"/>
      <mass value="${m}"/>
      <inertia ixx="${(m/12) * (3*r*r + h*h)}" ixy="0.0" ixz="0.0"
               iyy="${(m/12) * (3*r*r + h*h)}" iyz="0.0"
               izz="${(m/2) * (r*r)}"/>
    </inertial>
  </xacro:macro>

  <xacro:macro name="box_inertia" params="m x y z">
    <inertial>
      <origin xyz="0 0 ${z/2}" rpy="0 0 0"/>
      <mass value="${m}"/>
      <inertia ixx="${(m/12) * (y*y + z*z)}" ixy="0.0" ixz="0.0"
               iyy="${(m/12) * (x*x + z*z)}" iyz="0.0"
               izz="${(m/12) * (x*x + y*y)}"/>
    </inertial>
  </xacro:macro>

  <link name="base_footprint"/>

  <joint name="base_joint" type="fixed">
    <parent link="base_footprint"/>
    <child link="base_link"/>
    <origin xyz="0 0 0.05" rpy="0 0 0"/>
  </joint>

  <link name="base_link">
    <visual>
      <origin xyz="0 0 0.05" rpy="0 0 0"/>
      <geometry><cylinder radius="0.1" length="0.1"/></geometry>
      <material name="grey"/>
    </visual>
    <collision>
      <origin xyz="0 0 0.05" rpy="0 0 0"/>
      <geometry><cylinder radius="0.1" length="0.1"/></geometry>
    </collision>
    <xacro:cylinder_inertia m="5.0" r="0.1" h="0.1"/>
  </link>

  <joint name="joint_1" type="revolute">
    <parent link="base_link"/>
    <child link="link_1"/>
    <origin xyz="0 0 0.1" rpy="0 0 0"/>
    <axis xyz="0 0 1"/>
    <limit lower="-3.14" upper="3.14" effort="100" velocity="1.0"/>
  </joint>

  <!-- UPDATED: length = 0.5 -->
  <link name="link_1">
    <visual>
      <origin xyz="0 0 0.25" rpy="0 0 0"/>
      <geometry><cylinder radius="0.05" length="0.5"/></geometry>
      <material name="blue"/>
    </visual>

    <collision>
      <origin xyz="0 0 0.25" rpy="0 0 0"/>
      <geometry><cylinder radius="0.05" length="0.5"/></geometry>
    </collision>

    <!-- UPDATED inertia for h = 0.5 -->
    <xacro:cylinder_inertia m="2.0" r="0.05" h="0.5"/>
  </link>

  <joint name="joint_2" type="revolute">
    <parent link="link_1"/>
    <child link="link_2"/>
    <!-- moved to top of new link_1 -->
    <origin xyz="0 0 0.5" rpy="0 0 0"/>
    <axis xyz="0 1 0"/>
    <limit lower="-1.57" upper="1.57" effort="100" velocity="1.0"/>
  </joint>

  <link name="link_2">
    <visual>
      <origin xyz="0 0 0.2" rpy="0 0 0"/>
      <geometry><box size="0.05 0.05 0.4"/></geometry>
      <material name="orange"/>
    </visual>
    <collision>
      <origin xyz="0 0 0.2" rpy="0 0 0"/>
      <geometry><box size="0.05 0.05 0.4"/></geometry>
    </collision>
    <xacro:box_inertia m="1.5" x="0.05" y="0.05" z="0.4"/>
  </link>

  <!-- UPDATED x = 0.06 -->
  <joint name="ultrasonic_joint" type="fixed">
    <parent link="link_1"/>
    <child link="ultrasonic_link"/>
    <origin xyz="0.06 0 0.2" rpy="0 0 0"/>
  </joint>

  <link name="ultrasonic_link">
    <visual>
      <geometry><box size="0.02 0.05 0.02"/></geometry>
      <material name="black"/>
    </visual>
    <collision>
      <geometry><box size="0.02 0.05 0.02"/></geometry>
    </collision>
    <xacro:box_inertia m="0.1" x="0.02" y="0.05" z="0.02"/>
  </link>

<gazebo reference="ultrasonic_link">
  <sensor name="ultrasonic_sensor" type="gpu_lidar"> <always_on>1</always_on>
    <update_rate>10</update_rate>
    <visualize>true</visualize>
    <topic>/arm/scan</topic> <lidar>
      <scan>
        <horizontal>
          <samples>5</samples>
          <resolution>1</resolution>
          <min_angle>-0.15</min_angle>
          <max_angle>0.15</max_angle>
        </horizontal>
      </scan>
      <range>
        <min>0.1</min> <max>2.0</max>
      </range>
    </lidar>
    <plugin filename="gz-sim-sensors-system" name="gz::sim::systems::Sensors">
      <render_engine>ogre2</render_engine>
    </plugin>
  </sensor>
</gazebo>
 

  <gazebo>
    <plugin filename="gz-sim-joint-state-publisher-system" name="gz::sim::systems::JointStatePublisher">
      <topic>joint_states</topic>
    </plugin>

    <plugin filename="gz-sim-joint-position-controller-system" name="gz::sim::systems::JointPositionController">
      <joint_name>joint_1</joint_name>
      <topic>/model/manipulator/joint/joint_1/cmd_pos</topic>
    </plugin>

    <plugin filename="gz-sim-joint-position-controller-system" name="gz::sim::systems::JointPositionController">
      <joint_name>joint_2</joint_name>
      <topic>/model/manipulator/joint/joint_2/cmd_pos</topic>
    </plugin>
  </gazebo>

</robot>